Workbook

Sheet Cover
H9: Group 6 - BookBuddi
H13: BookBuddi
H17: WBS Estimate
H27: Revision No. : | U27: 1.4
H28: Modified By – Date : | U28: Denampo, Elwison - 2025/11/17
H29: Preliminary Review and Approval – Date : | U29: Last Name, First Name - yyyy/mm/dd
H30: Final Review and Approval – Date : | U30: Last Name, First Name - yyyy/mm/dd

Sheet Revision History
H1: REVISION HISTORY | K1: REVISION HISTORY
A6: REV NO | C6: MODIFIED BY | J6: MODIFIED DATE | N6: REMARKS | AB6: PRELIMINARY REVIEW AND APPROVAL | AI6: DATE REVIEWED | AN6: FINAL REVIEW AND APPROVAL | AU6: DATE APPROVED
A8: 1 | C8: Denampo, Elwison | J8: 45892 | N8: Initial Creation | AB8: Last Name, First Name | AI8: yyyy/mm/dd | AN8: Last Name, First Name | AU8: yyyy/mm/dd
A9: 1.1 | C9: Denampo, Elwison | J9: 45973 | N9: Addition of Cover, Revision History, Function List | AB9: Last Name, First Name | AI9: yyyy/mm/dd | AN9: Last Name, First Name | AU9: yyyy/mm/dd
A10: 1.2 | C10: Denampo, Elwison | J10: 45974 | N10: Revision of Jumpstart Progam Schedule | AB10: Last Name, First Name | AI10: yyyy/mm/dd | AN10: Last Name, First Name | AU10: yyyy/mm/dd
C11: Rivera, Marc Gerard
A12: 1.3 | C12: Denampo, Elwison | J12: 45976 | N12: Revision of Function List (Added entries) | AB12: Last Name, First Name | AI12: yyyy/mm/dd | AN12: Last Name, First Name | AU12: yyyy/mm/dd
A13: 1.4 | C13: Denampo, Elwison | J13: 45978 | N13: Revision of Jumpstart Progam Schedule, and Function List | AB13: Last Name, First Name | AI13: yyyy/mm/dd | AN13: Last Name, First Name | AU13: yyyy/mm/dd

Sheet Function List
A2: WBS Reference | B2: MODULE | C2: FUNCTION / DESCRIPTION / ASSUMPTIONS | D2: Type | F2: Estimate (MD) | G2: Remarks
A4: =_xlfn.XLOOKUP(B4, 'Jumpstart Program Schedule'!G:G, 'Jumpstart Program Schedule'!F:F) -> 13 | B4: ='Jumpstart Program Schedule'!G14 -> LANDING PAGE | F4: =_xlfn.XLOOKUP(B4, 'Jumpstart Program Schedule'!G:G, 'Jumpstart Program Schedule'!J:J) -> 5
C5: The main entry point of the system that introduces users to the library catalogue and provides access to login, registration, and book search functions. | D5: Web
A6: =_xlfn.XLOOKUP(B6, 'Jumpstart Program Schedule'!G:G, 'Jumpstart Program Schedule'!F:F) -> 15 | B6: ='Jumpstart Program Schedule'!G16 -> AUTHENTICATION | F6: =_xlfn.XLOOKUP(B6, 'Jumpstart Program Schedule'!G:G, 'Jumpstart Program Schedule'!J:J) -> 5
A7: =_xlfn.XLOOKUP(B7, 'Jumpstart Program Schedule'!G:G, 'Jumpstart Program Schedule'!F:F) -> 16 | B7: ='Jumpstart Program Schedule'!G17 -> LOGIN PAGE | C7: Allows users to securely log into their accounts using their registered credentials with authentication via email | D7: Web | F7: =_xlfn.XLOOKUP(B7, 'Jumpstart Program Schedule'!G:G, 'Jumpstart Program Schedule'!J:J) -> 3
A8: =_xlfn.XLOOKUP(B8, 'Jumpstart Program Schedule'!G:G, 'Jumpstart Program Schedule'!F:F) -> 20 | B8: ='Jumpstart Program Schedule'!G21 -> REGISTER/SIGNUP | C8: Allows users to securely register their credentials to have stored in the database with additional authentication via email. | D8: Web | F8: =_xlfn.XLOOKUP(B8, 'Jumpstart Program Schedule'!G:G, 'Jumpstart Program Schedule'!J:J) -> 1
A9: =_xlfn.XLOOKUP(B9, 'Jumpstart Program Schedule'!G:G, 'Jumpstart Program Schedule'!F:F) -> 25 | B9: ='Jumpstart Program Schedule'!G26 -> FORGOT PASSWORD | C9: Allows users to recover their accounts and reset/change their passwords via their registered email | D9: Web | F9: =_xlfn.XLOOKUP(B9, 'Jumpstart Program Schedule'!G:G, 'Jumpstart Program Schedule'!J:J) -> 4
A10: =_xlfn.XLOOKUP(B10, 'Jumpstart Program Schedule'!G:G, 'Jumpstart Program Schedule'!F:F) -> 31 | B10: ='Jumpstart Program Schedule'!G32 -> BOOK CATALOGUE | F10: =_xlfn.XLOOKUP(B10, 'Jumpstart Program Schedule'!G:G, 'Jumpstart Program Schedule'!J:J) -> 7
A11: =_xlfn.XLOOKUP(B11, 'Jumpstart Program Schedule'!G:G, 'Jumpstart Program Schedule'!F:F) -> 32 | B11: ='Jumpstart Program Schedule'!G33 -> LIST | C11: Displays a paginated list or grid of all available books in the public catalog. | D11: Web | F11: =_xlfn.XLOOKUP(B11, 'Jumpstart Program Schedule'!G:G, 'Jumpstart Program Schedule'!J:J) -> 5
A12: =_xlfn.XLOOKUP(B12, 'Jumpstart Program Schedule'!G:G, 'Jumpstart Program Schedule'!F:F) -> 37 | B12: ='Jumpstart Program Schedule'!G38 -> VIEW | C12: Displays the full, detailed page for a single book when selected from the list. | D12: Web | F12: =_xlfn.XLOOKUP(B12, 'Jumpstart Program Schedule'!G:G, 'Jumpstart Program Schedule'!J:J) -> 5
A13: =_xlfn.XLOOKUP(B13, 'Jumpstart Program Schedule'!G:G, 'Jumpstart Program Schedule'!F:F) -> 42 | B13: ='Jumpstart Program Schedule'!G43 -> SEARCH | C13: Implements the backend logic to filter the book list based on user queries (title, author, genre). | D13: Web | F13: =_xlfn.XLOOKUP(B13, 'Jumpstart Program Schedule'!G:G, 'Jumpstart Program Schedule'!J:J) -> 2
A14: =_xlfn.XLOOKUP(B14, 'Jumpstart Program Schedule'!G:G, 'Jumpstart Program Schedule'!F:F) -> 46 | B14: ='Jumpstart Program Schedule'!G47 -> BORROWING SYSTEM | F14: =_xlfn.XLOOKUP(B14, 'Jumpstart Program Schedule'!G:G, 'Jumpstart Program Schedule'!J:J) -> 8
A15: =_xlfn.XLOOKUP(B15, 'Jumpstart Program Schedule'!G:G, 'Jumpstart Program Schedule'!F:F) -> 32 | B15: ='Jumpstart Program Schedule'!G48 -> LIST | C15: Displays the list of books currently borrowed by the logged-in user, including due dates. | D15: Web | F15: =_xlfn.XLOOKUP(B15, 'Jumpstart Program Schedule'!G:G, 'Jumpstart Program Schedule'!J:J) -> 5
A16: =_xlfn.XLOOKUP(B16, 'Jumpstart Program Schedule'!G:G, 'Jumpstart Program Schedule'!F:F) -> 51 | B16: ='Jumpstart Program Schedule'!G52 -> ADD (Borrow Book) | C16: Implements the function for a user to check out an available book and adds a new record to their borrowing history. | D16: Web | F16: =_xlfn.XLOOKUP(B16, 'Jumpstart Program Schedule'!G:G, 'Jumpstart Program Schedule'!J:J) -> 1
A17: =_xlfn.XLOOKUP(B17, 'Jumpstart Program Schedule'!G:G, 'Jumpstart Program Schedule'!F:F) -> 57 | B17: ='Jumpstart Program Schedule'!G58 -> EDIT (Return Book) | C17: Implements the function for a user to return a borrowed book, updating its status to "available". | D17: Web | F17: =_xlfn.XLOOKUP(B17, 'Jumpstart Program Schedule'!G:G, 'Jumpstart Program Schedule'!J:J) -> 1
A18: =_xlfn.XLOOKUP(B18, 'Jumpstart Program Schedule'!G:G, 'Jumpstart Program Schedule'!F:F) -> 63 | B18: ='Jumpstart Program Schedule'!G64 -> VIEW (History) | C18: Displays a read-only list of all past books the user has borrowed and returned. | D18: Web | F18: =_xlfn.XLOOKUP(B18, 'Jumpstart Program Schedule'!G:G, 'Jumpstart Program Schedule'!J:J) -> 3
A19: =_xlfn.XLOOKUP(B19, 'Jumpstart Program Schedule'!G:G, 'Jumpstart Program Schedule'!F:F) -> 67 | B19: ='Jumpstart Program Schedule'!G68 -> REQUEST | C19: Provides a form for users to request a new book title that is not in the catalog. | D19: Web | F19: =_xlfn.XLOOKUP(B19, 'Jumpstart Program Schedule'!G:G, 'Jumpstart Program Schedule'!J:J) -> 5
A20: =_xlfn.XLOOKUP(B20, 'Jumpstart Program Schedule'!G:G, 'Jumpstart Program Schedule'!F:F) -> 72 | B20: ='Jumpstart Program Schedule'!G73 -> NOTIFICATIONS (User-Facing) | F20: =_xlfn.XLOOKUP(B20, 'Jumpstart Program Schedule'!G:G, 'Jumpstart Program Schedule'!J:J) -> 3
A21: =_xlfn.XLOOKUP(B21, 'Jumpstart Program Schedule'!G:G, 'Jumpstart Program Schedule'!F:F) -> 73 | B21: ='Jumpstart Program Schedule'!G74 -> Notification Dropdown | C21: The "bell" icon or list showing recent, unread notifications. | D21: Web | F21: =_xlfn.XLOOKUP(B21, 'Jumpstart Program Schedule'!G:G, 'Jumpstart Program Schedule'!J:J) -> 1
A22: =_xlfn.XLOOKUP(B22, 'Jumpstart Program Schedule'!G:G, 'Jumpstart Program Schedule'!F:F) -> 77 | B22: ='Jumpstart Program Schedule'!G78 -> Notification Page | C22: A dedicated page showing all of the user's past and present notifications. | D22: Web | F22: =_xlfn.XLOOKUP(B22, 'Jumpstart Program Schedule'!G:G, 'Jumpstart Program Schedule'!J:J) -> 1
A23: =_xlfn.XLOOKUP(B23, 'Jumpstart Program Schedule'!G:G, 'Jumpstart Program Schedule'!F:F) -> 80 | B23: ='Jumpstart Program Schedule'!G81 -> ADMIN PANEL | F23: =_xlfn.XLOOKUP(B23, 'Jumpstart Program Schedule'!G:G, 'Jumpstart Program Schedule'!J:J) -> 6
A24: =_xlfn.XLOOKUP(B24, 'Jumpstart Program Schedule'!G:G, 'Jumpstart Program Schedule'!F:F) -> 81 | B24: ='Jumpstart Program Schedule'!G82 -> LOGIN | C24: Allows specific admin accounts to securely log in using their registered (or provided) credentials | D24: Web | F24: =_xlfn.XLOOKUP(B24, 'Jumpstart Program Schedule'!G:G, 'Jumpstart Program Schedule'!J:J) -> 2
A25: =_xlfn.XLOOKUP(B25, 'Jumpstart Program Schedule'!G:G, 'Jumpstart Program Schedule'!F:F) -> 85 | B25: ='Jumpstart Program Schedule'!G86 -> DASHBOARD | C25: The admin's main homepage showing key statistics and summaries. | D25: Web | F25: =_xlfn.XLOOKUP(B25, 'Jumpstart Program Schedule'!G:G, 'Jumpstart Program Schedule'!J:J) -> 2
A26: =_xlfn.XLOOKUP(B26, 'Jumpstart Program Schedule'!G:G, 'Jumpstart Program Schedule'!F:F) -> 89 | B26: ='Jumpstart Program Schedule'!G90 -> USER MANAGEMENT | C26: Allows the admin to manage users/members registered in the catalogue. | D26: Web | F26: =_xlfn.XLOOKUP(B26, 'Jumpstart Program Schedule'!G:G, 'Jumpstart Program Schedule'!J:J) -> 2
A27: ='Jumpstart Program Schedule'!F91 -> 90 | B27: ='Jumpstart Program Schedule'!G91 -> LIST | C27: Displays a paginated and searchable list of all registered users in the system. | D27: Web | F27: =_xlfn.XLOOKUP(B27, 'Jumpstart Program Schedule'!G:G, 'Jumpstart Program Schedule'!J:J) -> 5
A28: =_xlfn.XLOOKUP(B28, 'Jumpstart Program Schedule'!G:G, 'Jumpstart Program Schedule'!F:F) -> 94 | B28: ='Jumpstart Program Schedule'!G95 -> ADD | C28: Provides an admin form to manually create a new user account. | D28: Web | F28: =_xlfn.XLOOKUP(B28, 'Jumpstart Program Schedule'!G:G, 'Jumpstart Program Schedule'!J:J) -> 2
A29: =_xlfn.XLOOKUP(B29, 'Jumpstart Program Schedule'!G:G, 'Jumpstart Program Schedule'!F:F) -> 98 | B29: ='Jumpstart Program Schedule'!G99 -> EDIT | C29: Provides an admin form to modify an existing user's details (e.g., reset password, change role). | D29: Web | F29: =_xlfn.XLOOKUP(B29, 'Jumpstart Program Schedule'!G:G, 'Jumpstart Program Schedule'!J:J) -> 2
A30: =_xlfn.XLOOKUP(B30, 'Jumpstart Program Schedule'!G:G, 'Jumpstart Program Schedule'!F:F) -> 102 | B30: ='Jumpstart Program Schedule'!G103 -> DELETE | C30: Implements the function for an admin to deactivate or permanently remove a user account. | D30: Web | F30: =_xlfn.XLOOKUP(B30, 'Jumpstart Program Schedule'!G:G, 'Jumpstart Program Schedule'!J:J) -> 2
A31: ='Jumpstart Program Schedule'!F107 -> 106 | B31: ='Jumpstart Program Schedule'!G107 -> VIEW | C31: Displays a read-only page showing the full profile and borrowing history of a single user. | D31: Web | F31: =_xlfn.XLOOKUP(B31, 'Jumpstart Program Schedule'!G:G, 'Jumpstart Program Schedule'!J:J) -> 5
A32: =_xlfn.XLOOKUP(B32, 'Jumpstart Program Schedule'!G:G, 'Jumpstart Program Schedule'!F:F) -> 110 | B32: ='Jumpstart Program Schedule'!G111 -> BOOK MANAGEMENT | C32: Allows the admin to manage books in the catalogue. | D32: Web | F32: =_xlfn.XLOOKUP(B32, 'Jumpstart Program Schedule'!G:G, 'Jumpstart Program Schedule'!J:J) -> 2
A33: 111 | B33: ='Jumpstart Program Schedule'!G112 -> LIST | C33: Displays a paginated and searchable list of all books in the database (both available and borrowed). | D33: Web | F33: =_xlfn.XLOOKUP(B33, 'Jumpstart Program Schedule'!G:G, 'Jumpstart Program Schedule'!J:J) -> 5
A34: 115 | B34: ='Jumpstart Program Schedule'!G116 -> ADD | C34: Provides an admin form to add a new book to the catalog, including its title, author, and cover image. | D34: Web | F34: =_xlfn.XLOOKUP(B34, 'Jumpstart Program Schedule'!G:G, 'Jumpstart Program Schedule'!J:J) -> 2
A35: 120 | B35: ='Jumpstart Program Schedule'!G121 -> EDIT | C35: Provides an admin form to modify an existing book's details (e.g., update description, change ISBN). | D35: Web | F35: =_xlfn.XLOOKUP(B35, 'Jumpstart Program Schedule'!G:G, 'Jumpstart Program Schedule'!J:J) -> 2
A36: 124 | B36: ='Jumpstart Program Schedule'!G125 -> DELETE | C36: Implements the function for an admin to permanently remove a book from the catalog. | D36: Web | F36: =_xlfn.XLOOKUP(B36, 'Jumpstart Program Schedule'!G:G, 'Jumpstart Program Schedule'!J:J) -> 2
A37: 128 | B37: ='Jumpstart Program Schedule'!G129 -> VIEW | C37: Displays a read-only page showing the full details and borrowing history for a single book. | D37: Web | F37: =_xlfn.XLOOKUP(B37, 'Jumpstart Program Schedule'!G:G, 'Jumpstart Program Schedule'!J:J) -> 5
A38: =_xlfn.XLOOKUP(B38, 'Jumpstart Program Schedule'!G:G, 'Jumpstart Program Schedule'!F:F) -> 132 | B38: ='Jumpstart Program Schedule'!G133 -> CATEGORY MANAGEMENT | C38: Allows the admin to manage book genres/categories (e.g., 'Fiction', 'Sci-Fi') in the catalogue. | D38: Web | F38: =_xlfn.XLOOKUP(B38, 'Jumpstart Program Schedule'!G:G, 'Jumpstart Program Schedule'!J:J) -> 2
A39: 133 | B39: ='Jumpstart Program Schedule'!G134 -> LIST | C39: Displays a list of all book categories/genres. | D39: Web | F39: =_xlfn.XLOOKUP(B39, 'Jumpstart Program Schedule'!G:G, 'Jumpstart Program Schedule'!J:J) -> 5
A40: 136 | B40: ='Jumpstart Program Schedule'!G137 -> ADD | C40: Provides a form or input to create a new book category. | D40: Web | F40: =_xlfn.XLOOKUP(B40, 'Jumpstart Program Schedule'!G:G, 'Jumpstart Program Schedule'!J:J) -> 2
A41: 140 | B41: ='Jumpstart Program Schedule'!G141 -> EDIT | C41: Implements the function to rename an existing category. | D41: Web | F41: =_xlfn.XLOOKUP(B41, 'Jumpstart Program Schedule'!G:G, 'Jumpstart Program Schedule'!J:J) -> 2
A42: 143 | B42: ='Jumpstart Program Schedule'!G144 -> DELETE | C42: Implements the function to remove an existing category. | D42: Web | F42: =_xlfn.XLOOKUP(B42, 'Jumpstart Program Schedule'!G:G, 'Jumpstart Program Schedule'!J:J) -> 2
...

Sheet Jumpstart Program Schedule
A1: Denampo, Elwison | B1: Osorio, Raphael | C1: Siloy, Jaspher Lawrence | D1: Vega, Flexter | E1: Rivera, Marc Gerard | F1: WBS | G1: Task | H1: Baseline Start | I1: Baseline End | J1: Days | K1: Predecessors | L1: Actual Days Data | M1: Actual Start | N1: Actual End
A2: x | B2: x | C2: x | D2: x | E2: x | F2: 1 | G2: PROJECT MANAGEMENT | H2: 45892 | I2: 45981 | J2: =DAYS360(H2,I2)+1 -> 88 | K2: - | L2: =DAYS360(M2,N2)+1 -> 88 | M2: 45892 | N2: 45981
A3: x | B3: x | C3: x | D3: x | E3: x | F3: 2 | G3: Creation of Project Plan | H3: 45892 | I3: 45899 | J3: =DAYS360(H3,I3)+1 -> 8 | K3: - | L3: =DAYS360(M3,N3)+1 -> 8 | M3: 45892 | N3: 45899
A4: x | B4: x | C4: x | D4: x | E4: x | F4: 3 | G4: Creation of WBS | H4: 45892 | I4: 45899 | J4: =DAYS360(H4,I4)+1 -> 8 | K4: 2 | L4: =DAYS360(M4,N4)+1 -> 8 | M4: 45892 | N4: 45899
A5: x | B5: x | C5: x | D5: x | E5: x | F5: 4 | G5: Creation of HLD | H5: 45892 | I5: 45978 | J5: =DAYS360(H5,I5)+1 -> 85 | K5: 3 | L5: =DAYS360(M5,N5)+1 -> 85 | M5: 45892 | N5: 45978
A6: x | B6: x | C6: x | D6: x | E6: x | F6: 5 | G6: PROJECT STRUCTURE | H6: 45892 | I6: 45969 | J6: =DAYS360(H6,I6)+1 -> 76 | K6: 4 | L6: =DAYS360(M6,N6)+1 -> 76 | M6: 45892 | N6: 45969
B7: x | C7: x | F7: 6 | G7: Figma Wireframe | H7: 45913 | I7: 45915 | J7: =DAYS360(H7,I7)+1 -> 3 | K7: 5 | L7: =DAYS360(M7,N7)+1 -> 3 | M7: 45913 | N7: 45915
B8: x | C8: x | F8: 7 | G8: Color Palette Selection and Logo | H8: 45913 | I8: 45918 | J8: =DAYS360(H8,I8)+1 -> 6 | K8: 6 | L8: =DAYS360(M8,N8)+1 -> 6 | M8: 45913 | N8: 45918
B9: x | C9: x | F9: 8 | G9: Finding References | H9: 45913 | I9: 45914 | J9: =DAYS360(H9,I9)+1 -> 2 | K9: 7 | L9: =DAYS360(M9,N9)+1 -> 2 | M9: 45913 | N9: 45914
A10: x | F10: 9 | G10: ERD Creation | H10: 45914 | I10: 45918 | J10: =DAYS360(H10,I10)+1 -> 5 | K10: 8 | L10: =DAYS360(M10,N10)+1 -> 5 | M10: 45914 | N10: 45918
A11: x | F11: 10 | G11: Initialization of Database | H11: 45920 | I11: 45923 | J11: =DAYS360(H11,I11)+1 -> 4 | K11: 9 | L11: =DAYS360(M11,N11)+1 -> 4 | M11: 45920 | N11: 45923
A12: x | F12: 11 | G12: Project Hierarchy | H12: 45920 | I12: 45923 | J12: =DAYS360(H12,I12)+1 -> 4 | K12: 10 | L12: =DAYS360(M12,N12)+1 -> 4 | M12: 45920 | N12: 45923
A13: x | B13: x | C13: x | D13: x | E13: x | F13: 12 | G13: DEVELOPMENT | H13: 45920 | I13: 45981 | J13: =DAYS360(H13,I13)+1 -> 61 | K13: 11 | L13: =DAYS360(M13,N13)+1 -> 61 | M13: 45920 | N13: 45981
B14: x | C14: x | F14: 13 | G14: LANDING PAGE | H14: 45920 | I14: 45924 | J14: =DAYS360(H14,I14)+1 -> 5 | K14: 12 | L14: =DAYS360(M14,N14)+1 -> 5 | M14: 45920 | N14: 45924
B15: x | C15: x | F15: 14 | G15: Creating of Landing Page (Frontend) | H15: 45920 | I15: 45924 | J15: =DAYS360(H15,I15)+1 -> 5 | K15: 13 | L15: =DAYS360(M15,N15)+1 -> 5 | M15: 45920 | N15: 45924
A16: x | B16: x | C16: x | D16: x | E16: x | F16: 15 | G16: AUTHENTICATION | H16: 45920 | I16: 45924 | J16: =DAYS360(H16,I16)+1 -> 5 | K16: 14 | L16: =DAYS360(M16,N16)+1 -> 5 | M16: 45920 | N16: 45924
A17: x | B17: x | C17: x | F17: 16 | G17: LOGIN PAGE | H17: 45921 | I17: 45923 | J17: =DAYS360(H17,I17)+1 -> 3 | K17: 15 | L17: =DAYS360(M17,N17)+1 -> 3 | M17: 45921 | N17: 45923
B18: x | C18: x | F18: 17 | G18: Design and Implement Frontend | H18: 45921 | I18: 45924 | J18: =DAYS360(H18,I18)+1 -> 4 | K18: 16 | L18: =DAYS360(M18,N18)+1 -> 4 | M18: 45921 | N18: 45924
A19: x | F19: 18 | G19: Configure Authentication from Backend | H19: 45917 | I19: 45926 | J19: =DAYS360(H19,I19)+1 -> 10 | K19: 17 | L19: =DAYS360(M19,N19)+1 -> 10 | M19: 45917 | N19: 45926
A20: x | D20: x | E20: x | F20: 19 | G20: Validate and Connect Frontend with Backend | H20: 45917 | I20: 45917 | J20: =DAYS360(H20,I20)+1 -> 1 | K20: 18 | L20: =DAYS360(M20,N20)+1 -> 1 | M20: 45917 | N20: 45917
A21: x | B21: x | C21: x | D21: x | E21: x | F21: 20 | G21: REGISTER/SIGNUP | H21: 45917 | I21: 45917 | J21: =DAYS360(H21,I21)+1 -> 1 | K21: 19 | L21: =DAYS360(M21,N21)+1 -> 1 | M21: 45917 | N21: 45917
B22: x | C22: x | F22: 21 | G22: Design and Implement Frontend | H22: 45917 | I22: 45922 | J22: =DAYS360(H22,I22)+1 -> 6 | K22: 20 | L22: =DAYS360(M22,N22)+1 -> 6 | M22: 45917 | N22: 45922
A23: x | F23: 22 | G23: Configure Authentication from Backend | H23: 45917 | I23: 45922 | J23: =DAYS360(H23,I23)+1 -> 6 | K23: 21 | L23: =DAYS360(M23,N23)+1 -> 6 | M23: 45917 | N23: 45922
A24: x | D24: x | E24: x | F24: 23 | G24: Validate and Connect Frontend with Backend | H24: 45917 | I24: 45924 | J24: =DAYS360(H24,I24)+1 -> 8 | K24: 22 | L24: =DAYS360(M24,N24)+1 -> 8 | M24: 45917 | N24: 45924
A25: x | F25: 24 | G25: Insert on new data on the database | H25: 45926 | I25: 45934 | J25: =DAYS360(H25,I25)+1 -> 9 | K25: 23 | L25: =DAYS360(M25,N25)+1 -> 9 | M25: 45926 | N25: 45934
A26: x | B26: x | C26: x | D26: x | E26: x | F26: 25 | G26: FORGOT PASSWORD | H26: 45928 | I26: 45931 | J26: =DAYS360(H26,I26)+1 -> 4 | K26: 24 | L26: =DAYS360(M26,N26)+1 -> 4 | M26: 45928 | N26: 45931
B27: x | C27: x | F27: 26 | G27: Design and Implement Frontend | H27: 45926 | I27: 45928 | J27: =DAYS360(H27,I27)+1 -> 3 | K27: 25 | L27: =DAYS360(M27,N27)+1 -> 3 | M27: 45926 | N27: 45928
A28: x | F28: 27 | G28: Configure Authentication from Backend | H28: 45928 | I28: 45929 | J28: =DAYS360(H28,I28)+1 -> 2 | K28: 26 | L28: =DAYS360(M28,N28)+1 -> 2 | M28: 45928 | N28: 45929
A29: x | D29: x | E29: x | F29: 28 | G29: Validate and Connect Frontend with Backend | H29: 45929 | I29: 45933 | J29: =DAYS360(H29,I29)+1 -> 5 | K29: 27 | L29: =DAYS360(M29,N29)+1 -> 5 | M29: 45929 | N29: 45933
A30: x | F30: 29 | G30: Validate token and Input for New Password | H30: 45929 | I30: 45934 | J30: =DAYS360(H30,I30)+1 -> 6 | K30: 28 | L30: =DAYS360(M30,N30)+1 -> 6 | M30: 45929 | N30: 45934
A31: x | F31: 30 | G31: Update User Password | H31: 45934 | I31: 45935 | J31: =DAYS360(H31,I31)+1 -> 2 | K31: 29 | L31: =DAYS360(M31,N31)+1 -> 2 | M31: 45934 | N31: 45935
A32: x | B32: x | C32: x | D32: x | E32: x | F32: 31 | G32: BOOK CATALOGUE | H32: 45936 | I32: 45942 | J32: =DAYS360(H32,I32)+1 -> 7 | K32: 30 | L32: =DAYS360(M32,N32)+1 -> 7 | M32: 45936 | N32: 45942
A33: x | B33: x | C33: x | D33: x | E33: x | F33: 32 | G33: LIST | H33: 45936 | I33: 45940 | J33: =DAYS360(H33,I33)+1 -> 5 | K33: 31 | L33: =DAYS360(M33,N33)+1 -> 5 | M33: 45936 | N33: 45940
B34: x | C34: x | E34: x | F34: 33 | G34: Design and Implement Frontend | H34: 45936 | I34: 45936 | J34: =DAYS360(H34,I34)+1 -> 1 | K34: 32 | L34: =DAYS360(M34,N34)+1 -> 1 | M34: 45936 | N34: 45936
A35: x | F35: 34 | G35: Fetch and display all books from database | H35: 45936 | I35: 45936 | J35: =DAYS360(H35,I35)+1 -> 1 | K35: 33 | L35: =DAYS360(M35,N35)+1 -> 1 | M35: 45936 | N35: 45936
D36: x | F36: 35 | G36: Implement Search Bar with Filters | H36: 45938 | I36: 45940 | J36: =DAYS360(H36,I36)+1 -> 3 | K36: 34 | L36: =DAYS360(M36,N36)+1 -> 3 | M36: 45938 | N36: 45940
A37: x | F37: 36 | G37: Implement Pagination | H37: 45937 | I37: 45937 | J37: =DAYS360(H37,I37)+1 -> 1 | K37: 35 | L37: =DAYS360(M37,N37)+1 -> 1 | M37: 45937 | N37: 45937
A38: x | B38: x | C38: x | E38: x | F38: 37 | G38: VIEW | H38: 45936 | I38: 45940 | J38: =DAYS360(H38,I38)+1 -> 5 | K38: 36 | L38: =DAYS360(M38,N38)+1 -> 5 | M38: 45936 | N38: 45940
B39: x | C39: x | E39: x | F39: 38 | G39: Design and Implement Frontend | H39: 45936 | I39: 45936 | J39: =DAYS360(H39,I39)+1 -> 1 | K39: 37 | L39: =DAYS360(M39,N39)+1 -> 1 | M39: 45936 | N39: 45936
A40: x | F40: 39 | G40: Fetch and display full book details | H40: 45936 | I40: 45936 | J40: =DAYS360(H40,I40)+1 -> 1 | K40: 38 | L40: =DAYS360(M40,N40)+1 -> 1 | M40: 45936 | N40: 45936
...
